Workbook

Sheet REKAP
O3: PEKERJAAN
P4: =IF(Q3="","",", ")
P5: =IF(Q5="",""," DAN ")
F6: REKAP RAB PEKERJAAN | O6: FUNGSI
F7: KONSTRUKSI JARINGAN DISTRIBUSI UP3 KUPANG | O7: LOKASI
B8: NAMA PEKERJAAN | E8: : | F8: =_xlfn.CONCAT(Q3,P4,Q4,P5,Q5," UNTUK ",Q6," LOKASI ",Q7) -> UNTUK LOKASI | O8: UNIT | Q8: ULP KUPANG
B9: UNIT | E9: : | F9: =Q8 -> ULP KUPANG | O9: KOTA/KAB | Q9: Kota Kupang
B11: NO | C11: URAIAN PEKERJAAN | G11: SATUAN | H11: VOLUME | I11: MDU (Rp) | J11: NON MDU (Rp) | K11: JASA (Rp) | L11: Harga Total (Rp)
B12: 1 | C12: =F8&" "&F9 -> UNTUK LOKASI ULP KUPANG
C13: a. | D13: Pembangunan JTM | G13: kms | H13: ='RAB Pasang'!F1050 -> 0 | I13: ='RAB Pasang'!L1062 -> 0 | J13: =SUM('RAB Pasang'!L1063:L1075) -> 0 | K13: ='RAB Pasang'!M1076 -> 0 | L13: =SUM(I13:K15) -> 0
C14: b. | D14: Pembangunan Gardu Distribusi | G14: unit | H14: ='RAB Pasang'!G1052 -> 0
C15: c. | D15: Perluasan JTR | G15: kms | H15: ='RAB Pasang'!H1051 -> 0
B16: 2 | C16: Jasa Pembongkaran | G16: lot | H16: =IF(L16>0,1,0) -> 0 | K16: ='RAB Bongkar'!M1076 -> 0 | L16: =SUM(I16:K16) -> 0
B17: 3 | C17: Jasa Perbaikan | G17: lot | H17: =IF(L17>0,1,0) -> 0 | K17: ='RAB Perbaikan'!M1076 -> 0 | L17: =SUM(I17:K17) -> 0
B19: ="Terbilang:"&CHAR(10)&PROPER(IF(L21=0,"nol",IF(L21<0,"minus ","")& SUBSTITUTE(TRIM(SUBSTITUTE(SUBSTITUTE(SUBSTITUTE(SUBSTITUTE(SUBSTITUTE(SUBSTITUTE(SUBSTITUTE(SUBSTITUTE(SUBSTITUTE(SUBSTITUTE(SUBSTITUTE(SUBSTITUTE(SUBSTITUTE(SUBSTITUTE(SUBSTITUTE(SUBSTITUTE(SUBSTITUTE(SUBSTITUTE(SUBSTITUTE(SUBSTITUTE(SUBSTITUTE(SUBSTITUTE(SUBSTITUTE(SUBSTITUTE( IF(--MID(TEXT(ABS(L21),"000000000000000"),1,3)=0,"",MID(TEXT(ABS(L21),"000000000000000"),1,1)&" ratus "&MID(TEXT(ABS(L21),"000000000000000"),2,1)&" puluh "&MID(TEXT(ABS(L21),"000000000000000"),3,1)&" trilyun ")& IF(--MID(TEXT(ABS(L21),"000000000000000"),4,3)=0,"",MID(TEXT(ABS(L21),"000000000000000"),4,1)&" ratus "&MID(TEXT(ABS(L21),"000000000000000"),5,1)&" puluh "&MID(TEXT(ABS(L21),"000000000000000"),6,1)&" milyar ")& IF(--MID(TEXT(ABS(L21),"000000000000000"),7,3)=0,"",MID(TEXT(ABS(L21),"000000000000000"),7,1)&" ratus "&MID(TEXT(ABS(L21),"000000000000000"),8,1)&" puluh "&MID(TEXT(ABS(L21),"000000000000000"),9,1)&" juta ")& IF(--MID(TEXT(ABS(L21),"000000000000000"),10,3)=0,"",IF(--MID(TEXT(ABS(L21),"000000000000000"),10,3)=1,"*",MID(TEXT(ABS(L21),"000000000000000"),10,1)&" ratus "&MID(TEXT(ABS(L21),"000000000000000"),11,1)&" puluh ")&MID(TEXT(ABS(L21),"000000000000000"),12,1)&" ribu ")& IF(--MID(TEXT(ABS(L21),"000000000000000"),13,3)=0,"",MID(TEXT(ABS(L21),"000000000000000"),13,1)&" ratus "&MID(TEXT(ABS(L21),"000000000000000"),14,1)&" puluh "&MID(TEXT(ABS(L21),"000000000000000"),15,1)),1,"satu"),2,"dua"),3,"tiga"),4,"empat"),5,"lima"),6,"enam"),7,"tujuh"),8,"delapan"),9,"sembilan"),"0 ratus",""),"0 puluh",""),"satu puluh 0","sepuluh"),"satu puluh satu","sebelas"),"satu puluh dua","dua belas"),"satu puluh tiga","tiga belas"),"satu puluh empat","empat belas"),"satu puluh lima","lima belas"),"satu puluh enam","enam belas"),"satu puluh tujuh","tujuh belas"),"satu puluh delapan","delapan belas"),"satu puluh sembilan","sembilan belas"),"satu ratus","seratus"),"*satu ribu","seribu"),0,""))," "," ")) & " rupiah") -> Terbilang: Nol Rupiah | H19: Jumlah | I19: =SUM(I13:I18) -> 0 | J19: =SUM(J13:J18) -> 0 | K19: =SUM(K13:K18) -> 0 | L19: =SUM(L13:L18) -> 0
H20: PPN 12% (12% x DPP Nilai Lain) | I20: =((11/12)*I19)*12% -> 0 | J20: =((11/12)*J19)*12% -> 0 | K20: =((11/12)*K19)*12% -> 0 | L20: =((11/12)*L19)*12% -> 0
H21: Total | I21: =SUM(I19:I20) -> 0 | J21: =SUM(J19:J20) -> 0 | K21: =SUM(K19:K20) -> 0 | L21: =SUM(L19:L20) -> 0

Sheet RAB Pasang
A4: RAB PEKERJAAN KONSTRUKSI JARINGAN DISTRIBUSI KUPANG - KHS 2026
A6: =REKAP!B8&REKAP!E8&REKAP!F8 -> NAMA PEKERJAAN : UNTUK LOKASI
A7: =REKAP!B9&REKAP!E9&REKAP!F9 -> UNIT : ULP KUPANG
A13: NO | B13: URAIAN MATERIAL / PEKERJAAN | E13: SATUAN | F13: VOLUME | J13: HARGA SATUAN | L13: HARGA BAGIAN | N13: JUMLAH HARGA | P13: Asumsi Ukuran | S13: Perkiraan Panjang | T13: Perkiraan Kubikasi
F14: JTM | G14: Gardu | H14: JTR | I14: Total | J14: BAHAN | K14: UPAH | L14: BAHAN | M14: UPAH | P14: P | Q14: L | R14: T
J15: (Rp) | K15: (Rp) | L15: (Rp) | M15: (Rp) | N15: (Rp) | P15: cm | Q15: cm | R15: cm | S15: m/haspel | T15: m3/item
A16: 1 | B16: 2 | E16: 3 | F16: 4 | G16: 5 | H16: 6 | I16: 7=4+5+6 | J16: 8 | K16: 9 | L16: 10=7x8 | M16: 11=7x9 | N16: 12=10+11 | P16: 13 | Q16: 14 | R16: 15 | S16: 16 | T16: 17=13x14x15/10^6/16
A18: A | B18: MATERIAL UTAMA (Disediakan PLN)
A19: 1 | B19: Mendirikan Tiang Beton 9 meter 200 daN | E19: batang | I19: =SUM(F19:H19) -> 0 | J19: 6304300 | K19: 1117820 | L19: =J19*I19 -> 0 | M19: =K19*I19 -> 0 | N19: =SUM(L19:M19) -> 0
A20: =A19+1 -> 2 | B20: Mendirikan Tiang Beton 12 meter 200 daN | E20: batang | I20: =SUM(F20:H20) -> 0 | J20: 9781500 | K20: 1597810 | L20: =J20*I20 -> 0 | M20: =K20*I20 -> 0 | N20: =SUM(L20:M20) -> 0
A21: =A20+1 -> 3 | B21: Mendirikan Tiang Beton 12 meter 350 daN | E21: batang | I21: =SUM(F21:H21) -> 0 | J21: 10485200 | K21: 1837810 | L21: =J21*I21 -> 0 | M21: =K21*I21 -> 0 | N21: =SUM(L21:M21) -> 0
A22: =A21+1 -> 4 | B22: Mendirikan Tiang Beton 13 meter 350 daN | E22: batang | I22: =SUM(F22:H22) -> 0 | J22: 11779400 | K22: 2130410 | L22: =J22*I22 -> 0 | M22: =K22*I22 -> 0 | N22: =SUM(L22:M22) -> 0
A23: =A22+1 -> 5 | B23: Mendirikan Tiang Beton 14 meter 350 daN | E23: batang | I23: =SUM(F23:H23) -> 0 | J23: 14194600 | K23: 3195620 | L23: =J23*I23 -> 0 | M23: =K23*I23 -> 0 | N23: =SUM(L23:M23) -> 0
A24: =A23+1 -> 6 | B24: Mendirikan Tiang Baja 7 meter 100 daN | E24: batang | I24: =SUM(F24:H24) -> 0 | K24: 449710 | L24: =J24*I24 -> 0 | M24: =K24*I24 -> 0 | N24: =SUM(L24:M24) -> 0
A25: =A24+1 -> 7 | B25: Mendirikan Tiang Baja 9 meter 100 daN | E25: batang | I25: =SUM(F25:H25) -> 0 | K25: 710140 | L25: =J25*I25 -> 0 | M25: =K25*I25 -> 0 | N25: =SUM(L25:M25) -> 0
A26: =A25+1 -> 8 | B26: Mendirikan Tiang Baja 9 meter 200 daN | E26: batang | I26: =SUM(F26:H26) -> 0 | J26: 3525160 | K26: 850450 | L26: =J26*I26 -> 0 | M26: =K26*I26 -> 0 | N26: =SUM(L26:M26) -> 0
A27: =A26+1 -> 9 | B27: Mendirikan Tiang Baja 11 meter 200 daN | E27: batang | I27: =SUM(F27:H27) -> 0 | K27: 996220 | L27: =J27*I27 -> 0 | M27: =K27*I27 -> 0 | N27: =SUM(L27:M27) -> 0
A28: =A27+1 -> 10 | B28: Mendirikan Tiang Baja 12 meter 200 daN | E28: batang | I28: =SUM(F28:H28) -> 0 | J28: 5302899 | K28: 1138530 | L28: =J28*I28 -> 0 | M28: =K28*I28 -> 0 | N28: =SUM(L28:M28) -> 0
A29: =A28+1 -> 11 | B29: Mendirikan Tiang Baja 12 meter 350 daN | E29: batang | I29: =SUM(F29:H29) -> 0 | J29: 6793340 | K29: 1328290 | L29: =J29*I29 -> 0 | M29: =K29*I29 -> 0 | N29: =SUM(L29:M29) -> 0
A30: =A29+1 -> 12 | B30: Mendirikan Tiang Baja 13 meter 350 daN | E30: batang | I30: =SUM(F30:H30) -> 0 | J30: 8963194 | K30: 1593950 | L30: =J30*I30 -> 0 | M30: =K30*I30 -> 0 | N30: =SUM(L30:M30) -> 0
A31: =A30+1 -> 13 | B31: Mendirikan Tiang Baja 14 meter 350 daN | E31: batang | I31: =SUM(F31:H31) -> 0 | J31: 11304450 | K31: 1755660 | L31: =J31*I31 -> 0 | M31: =K31*I31 -> 0 | N31: =SUM(L31:M31) -> 0
A32: =A31+1 -> 14 | B32: Pasang Isolator tumpu 20 kV Porcelin | E32: buah | I32: =SUM(F32:H32) -> 0 | J32: 289735 | K32: 68920 | L32: =J32*I32 -> 0 | M32: =K32*I32 -> 0 | N32: =SUM(L32:M32) -> 0 | P32: 15 | Q32: 15 | R32: 47 | S32: 0 | T32: =IF(S32=0,P32*Q32*R32/10^6,P32*Q32*R32/10^6/S32) -> 0.010575
A33: =A32+1 -> 15 | B33: Pasang Isolator tarik 20 kV Porcelin | E33: buah | I33: =SUM(F33:H33) -> 0 | J33: 621370 | K33: 75810 | L33: =J33*I33 -> 0 | M33: =K33*I33 -> 0 | N33: =SUM(L33:M33) -> 0 | P33: 30 | Q33: 25.4 | R33: 25.4 | S33: 0 | T33: =IF(S33=0,P33*Q33*R33/10^6,P33*Q33*R33/10^6/S33) -> 0.0193548
A34: =A33+1 -> 16 | B34: Pasang Isolator tumpu 20 kV Polimer | E34: buah | I34: =SUM(F34:H34) -> 0 | J34: 245400 | K34: 63180 | L34: =J34*I34 -> 0 | M34: =K34*I34 -> 0 | N34: =SUM(L34:M34) -> 0 | P34: 15 | Q34: 15 | R34: 47 | S34: 0 | T34: =IF(S34=0,P34*Q34*R34/10^6,P34*Q34*R34/10^6/S34) -> 0.010575
A35: =A34+1 -> 17 | B35: Pasang Isolator tarik 20 kV Polimer | E35: buah | I35: =SUM(F35:H35) -> 0 | J35: 246398 | K35: 68920 | L35: =J35*I35 -> 0 | M35: =K35*I35 -> 0 | N35: =SUM(L35:M35) -> 0 | P35: 73 | Q35: 17 | R35: 11 | S35: 0 | T35: =IF(S35=0,P35*Q35*R35/10^6,P35*Q35*R35/10^6/S35) -> 0.013651
A36: =A35+1 -> 18 | B36: Pasang Cut Out 20 kV | E36: buah | I36: =SUM(F36:H36) -> 0 | J36: 1269657 | K36: 68920 | L36: =J36*I36 -> 0 | M36: =K36*I36 -> 0 | N36: =SUM(L36:M36) -> 0 | P36: 50 | Q36: 37 | R36: 14.5 | S36: 0 | T36: =IF(S36=0,P36*Q36*R36/10^6,P36*Q36*R36/10^6/S36) -> 0.026825
A37: =A36+1 -> 19 | B37: Pasang Lightning Arrester 24 kV | E37: buah | I37: =SUM(F37:H37) -> 0 | J37: 699402 | K37: 68920 | L37: =J37*I37 -> 0 | M37: =K37*I37 -> 0 | N37: =SUM(L37:M37) -> 0 | P37: 24 | Q37: 17 | R37: 26 | S37: 0 | T37: =IF(S37=0,P37*Q37*R37/10^6,P37*Q37*R37/10^6/S37) -> 0.010608
A38: =A37+1 -> 20 | B38: Pasang Trafo 3 phs 25 kVA - 20 kV | E38: buah | I38: =SUM(F38:H38) -> 0 | K38: 1774970 | L38: =J38*I38 -> 0 | M38: =K38*I38 -> 0 | N38: =SUM(L38:M38) -> 0 | P38: 76 | Q38: 51 | R38: 102 | S38: 0 | T38: =IF(S38=0,P38*Q38*R38/10^6,P38*Q38*R38/10^6/S38) -> 0.395352
A39: =A38+1 -> 21 | B39: Pasang Trafo 3 phs 50 kVA - 20 kV | E39: buah | I39: =SUM(F39:H39) -> 0 | J39: 34652150 | K39: 1935380 | L39: =J39*I39 -> 0 | M39: =K39*I39 -> 0 | N39: =SUM(L39:M39) -> 0 | P39: 88 | Q39: 54 | R39: 111 | S39: 0 | T39: =IF(S39=0,P39*Q39*R39/10^6,P39*Q39*R39/10^6/S39) -> 0.527472
A40: =A39+1 -> 22 | B40: Pasang Trafo 3 phs 100 kVA - 20 kV | E40: buah | I40: =SUM(F40:H40) -> 0 | J40: 44603470 | K40: 2176000 | L40: =J40*I40 -> 0 | M40: =K40*I40 -> 0 | N40: =SUM(L40:M40) -> 0 | P40: 96 | Q40: 65 | R40: 116 | S40: 0 | T40: =IF(S40=0,P40*Q40*R40/10^6,P40*Q40*R40/10^6/S40) -> 0.72384
A41: =A40+1 -> 23 | B41: Pasang Trafo 3 phs 160 kVA - 20 kV | E41: buah | I41: =SUM(F41:H41) -> 0 | J41: 63981050 | K41: 2491700 | L41: =J41*I41 -> 0 | M41: =K41*I41 -> 0 | N41: =SUM(L41:M41) -> 0 | P41: 103 | Q41: 74 | R41: 128 | S41: 0 | T41: =IF(S41=0,P41*Q41*R41/10^6,P41*Q41*R41/10^6/S41) -> 0.975616
A42: =A41+1 -> 24 | B42: Pasang Trafo 3 phs 200 kVA - 20 kV | E42: buah | I42: =SUM(F42:H42) -> 0 | K42: 3050500 | L42: =J42*I42 -> 0 | M42: =K42*I42 -> 0 | N42: =SUM(L42:M42) -> 0 | P42: 107 | Q42: 81 | R42: 133 | S42: 0 | T42: =IF(S42=0,P42*Q42*R42/10^6,P42*Q42*R42/10^6/S42) -> 1.152711
A43: =A42+1 -> 25 | B43: Pasang Trafo 3 phs 250 kVA - 20 kV | E43: buah | I43: =SUM(F43:H43) -> 0 | J43: 75212870 | K43: 3214800 | L43: =J43*I43 -> 0 | M43: =K43*I43 -> 0 | N43: =SUM(L43:M43) -> 0 | P43: 114 | Q43: 84 | R43: 136 | S43: 0 | T43: =IF(S43=0,P43*Q43*R43/10^6,P43*Q43*R43/10^6/S43) -> 1.302336
A44: =A43+1 -> 26 | B44: Pasang Trafo 3 phs 400 kVA - 20 kV | E44: buah | I44: =SUM(F44:H44) -> 0 | J44: 93244590 | K44: 3372650 | L44: =J44*I44 -> 0 | M44: =K44*I44 -> 0 | N44: =SUM(L44:M44) -> 0 | P44: 132 | Q44: 91 | R44: 149 | S44: 0 | T44: =IF(S44=0,P44*Q44*R44/10^6,P44*Q44*R44/10^6/S44) -> 1.789788
A45: =A44+1 -> 27 | B45: Pasang Trafo 3 phs 630 kVA - 20 kV | E45: buah | I45: =SUM(F45:H45) -> 0 | J45: 128557200 | K45: 3536950 | L45: =J45*I45 -> 0 | M45: =K45*I45 -> 0 | N45: =SUM(L45:M45) -> 0 | P45: 145 | Q45: 104 | R45: 165 | S45: 0 | T45: =IF(S45=0,P45*Q45*R45/10^6,P45*Q45*R45/10^6/S45) -> 2.4882
A46: =A45+1 -> 28 | B46: Pasang Trafo 3 phs 1000 kVA - 20 kV | E46: buah | I46: =SUM(F46:H46) -> 0 | K46: 3694800 | L46: =J46*I46 -> 0 | M46: =K46*I46 -> 0 | N46: =SUM(L46:M46) -> 0 | P46: 166 | Q46: 112 | R46: 187 | S46: 0 | T46: =IF(S46=0,P46*Q46*R46/10^6,P46*Q46*R46/10^6/S46) -> 3.476704
A47: =A46+1 -> 29 | B47: Pasang Konduktor SUTM AAAC 3x35 mm² | E47: ms | I47: =SUM(F47:H47) -> 0 | K47: 6032.15 | L47: =J47*I47 -> 0 | M47: =K47*I47 -> 0 | N47: =SUM(L47:M47) -> 0 | P47: 145 | Q47: 145 | R47: 60 | S47: 3000 | T47: =IF(S47=0,P47*Q47*R47/10^6,P47*Q47*R47/10^6/S47) -> 0.0004205 | U47: Konversi satuan dan harga dari kms ke ms (KHS dalam kms)
A48: =A47+1 -> 30 | B48: Pasang Konduktor SUTM AAAC 3x50 mm² | E48: ms | I48: =SUM(F48:H48) -> 0 | K48: 7424.19 | L48: =J48*I48 -> 0 | M48: =K48*I48 -> 0 | N48: =SUM(L48:M48) -> 0 | P48: 145 | Q48: 145 | R48: 70 | S48: 3000 | T48: =IF(S48=0,P48*Q48*R48/10^6,P48*Q48*R48/10^6/S48) -> 0.00049058333 | U48: Konversi satuan dan harga dari kms ke ms (KHS dalam kms)
A49: =A48+1 -> 31 | B49: Pasang Konduktor SUTM AAAC 3x70 mm² | E49: ms | I49: =SUM(F49:H49) -> 0 | J49: 18516.333 | K49: 8774.04 | L49: =J49*I49 -> 0 | M49: =K49*I49 -> 0 | N49: =SUM(L49:M49) -> 0 | P49: 145 | Q49: 145 | R49: 85 | S49: 3000 | T49: =IF(S49=0,P49*Q49*R49/10^6,P49*Q49*R49/10^6/S49) -> 0.00059570833 | U49: Konversi satuan dan harga dari kms ke ms (KHS dalam kms)
A50: =A49+1 -> 32 | B50: Pasang Konduktor SUTM AAAC 3x95 mm² | E50: ms | I50: =SUM(F50:H50) -> 0 | K50: 10723.83 | L50: =J50*I50 -> 0 | M50: =K50*I50 -> 0 | N50: =SUM(L50:M50) -> 0 | P50: 145 | Q50: 145 | R50: 95 | S50: 2000 | T50: =IF(S50=0,P50*Q50*R50/10^6,P50*Q50*R50/10^6/S50) -> 0.0009986875 | U50: Konversi satuan dan harga dari kms ke ms (KHS dalam kms)
...

Sheet RAB Bongkar
A4: RAB PEKERJAAN PEMBONGKARAN KONSTRUKSI JARINGAN DISTRIBUSI KUPANG - KHS 2026
A6: =REKAP!B8&REKAP!E8&REKAP!F8 -> NAMA PEKERJAAN : UNTUK LOKASI
A7: =REKAP!B9&REKAP!E9&REKAP!F9 -> UNIT : ULP KUPANG
A13: NO | B13: URAIAN MATERIAL / PEKERJAAN | E13: SATUAN | F13: VOLUME | J13: HARGA SATUAN | L13: HARGA BAGIAN | N13: JUMLAH HARGA | P13: Asumsi Ukuran | S13: Perkiraan Panjang | T13: Perkiraan Kubikasi
F14: JTM | G14: Gardu | H14: JTR | I14: Total | J14: BAHAN | K14: UPAH | L14: BAHAN | M14: UPAH | P14: P | Q14: L | R14: T
J15: (Rp) | K15: (Rp) | L15: (Rp) | M15: (Rp) | N15: (Rp) | P15: cm | Q15: cm | R15: cm | S15: m/haspel | T15: m3/item
A16: 1 | B16: 2 | E16: 3 | F16: 4 | G16: 5 | H16: 6 | I16: 7=4+5+6 | J16: 8 | K16: 9 | L16: 10=7x8 | M16: 11=7x9 | N16: 12=10+11 | P16: 13 | Q16: 14 | R16: 15 | S16: 16 | T16: 17=13x14x15/10^6/16
A18: A | B18: MATERIAL UTAMA (Disediakan PLN)
A19: 1 | B19: Mendirikan Tiang Beton 9 meter 200 daN | E19: batang | I19: =SUM(F19:H19) -> 0 | K19: ='RAB Pasang'!K19*60% -> 670692 | L19: =J19*I19 -> 0 | M19: =K19*I19 -> 0 | N19: =SUM(L19:M19) -> 0
A20: =A19+1 -> 2 | B20: Mendirikan Tiang Beton 12 meter 200 daN | E20: batang | I20: =SUM(F20:H20) -> 0 | K20: ='RAB Pasang'!K20*60% -> 958686 | L20: =J20*I20 -> 0 | M20: =K20*I20 -> 0 | N20: =SUM(L20:M20) -> 0
A21: =A20+1 -> 3 | B21: Mendirikan Tiang Beton 12 meter 350 daN | E21: batang | I21: =SUM(F21:H21) -> 0 | K21: ='RAB Pasang'!K21*60% -> 1102686 | L21: =J21*I21 -> 0 | M21: =K21*I21 -> 0 | N21: =SUM(L21:M21) -> 0
A22: =A21+1 -> 4 | B22: Mendirikan Tiang Beton 13 meter 350 daN | E22: batang | I22: =SUM(F22:H22) -> 0 | K22: ='RAB Pasang'!K22*60% -> 1278246 | L22: =J22*I22 -> 0 | M22: =K22*I22 -> 0 | N22: =SUM(L22:M22) -> 0
A23: =A22+1 -> 5 | B23: Mendirikan Tiang Beton 14 meter 350 daN | E23: batang | I23: =SUM(F23:H23) -> 0 | K23: ='RAB Pasang'!K23*60% -> 1917372 | L23: =J23*I23 -> 0 | M23: =K23*I23 -> 0 | N23: =SUM(L23:M23) -> 0
A24: =A23+1 -> 6 | B24: Mendirikan Tiang Baja 7 meter 100 daN | E24: batang | I24: =SUM(F24:H24) -> 0 | K24: ='RAB Pasang'!K24*60% -> 269826 | L24: =J24*I24 -> 0 | M24: =K24*I24 -> 0 | N24: =SUM(L24:M24) -> 0
A25: =A24+1 -> 7 | B25: Mendirikan Tiang Baja 9 meter 100 daN | E25: batang | I25: =SUM(F25:H25) -> 0 | K25: ='RAB Pasang'!K25*60% -> 426084 | L25: =J25*I25 -> 0 | M25: =K25*I25 -> 0 | N25: =SUM(L25:M25) -> 0
A26: =A25+1 -> 8 | B26: Mendirikan Tiang Baja 9 meter 200 daN | E26: batang | I26: =SUM(F26:H26) -> 0 | K26: ='RAB Pasang'!K26*60% -> 510270 | L26: =J26*I26 -> 0 | M26: =K26*I26 -> 0 | N26: =SUM(L26:M26) -> 0
A27: =A26+1 -> 9 | B27: Mendirikan Tiang Baja 11 meter 200 daN | E27: batang | I27: =SUM(F27:H27) -> 0 | K27: ='RAB Pasang'!K27*60% -> 597732 | L27: =J27*I27 -> 0 | M27: =K27*I27 -> 0 | N27: =SUM(L27:M27) -> 0
A28: =A27+1 -> 10 | B28: Mendirikan Tiang Baja 12 meter 200 daN | E28: batang | I28: =SUM(F28:H28) -> 0 | K28: ='RAB Pasang'!K28*60% -> 683118 | L28: =J28*I28 -> 0 | M28: =K28*I28 -> 0 | N28: =SUM(L28:M28) -> 0
A29: =A28+1 -> 11 | B29: Mendirikan Tiang Baja 12 meter 350 daN | E29: batang | I29: =SUM(F29:H29) -> 0 | K29: ='RAB Pasang'!K29*60% -> 796974 | L29: =J29*I29 -> 0 | M29: =K29*I29 -> 0 | N29: =SUM(L29:M29) -> 0
A30: =A29+1 -> 12 | B30: Mendirikan Tiang Baja 13 meter 350 daN | E30: batang | I30: =SUM(F30:H30) -> 0 | K30: ='RAB Pasang'!K30*60% -> 956370 | L30: =J30*I30 -> 0 | M30: =K30*I30 -> 0 | N30: =SUM(L30:M30) -> 0
A31: =A30+1 -> 13 | B31: Mendirikan Tiang Baja 14 meter 350 daN | E31: batang | I31: =SUM(F31:H31) -> 0 | K31: ='RAB Pasang'!K31*60% -> 1053396 | L31: =J31*I31 -> 0 | M31: =K31*I31 -> 0 | N31: =SUM(L31:M31) -> 0
A32: =A31+1 -> 14 | B32: Pasang Isolator tumpu 20 kV Porcelin | E32: buah | I32: =SUM(F32:H32) -> 0 | K32: ='RAB Pasang'!K32*60% -> 41352 | L32: =J32*I32 -> 0 | M32: =K32*I32 -> 0 | N32: =SUM(L32:M32) -> 0 | P32: 15 | Q32: 15 | R32: 47 | S32: 0 | T32: =IF(S32=0,P32*Q32*R32/10^6,P32*Q32*R32/10^6/S32) -> 0.010575
A33: =A32+1 -> 15 | B33: Pasang Isolator tarik 20 kV Porcelin | E33: buah | I33: =SUM(F33:H33) -> 0 | K33: ='RAB Pasang'!K33*60% -> 45486 | L33: =J33*I33 -> 0 | M33: =K33*I33 -> 0 | N33: =SUM(L33:M33) -> 0 | P33: 30 | Q33: 25.4 | R33: 25.4 | S33: 0 | T33: =IF(S33=0,P33*Q33*R33/10^6,P33*Q33*R33/10^6/S33) -> 0.0193548
A34: =A33+1 -> 16 | B34: Pasang Isolator tumpu 20 kV Polimer | E34: buah | I34: =SUM(F34:H34) -> 0 | K34: ='RAB Pasang'!K34*60% -> 37908 | L34: =J34*I34 -> 0 | M34: =K34*I34 -> 0 | N34: =SUM(L34:M34) -> 0 | P34: 15 | Q34: 15 | R34: 47 | S34: 0 | T34: =IF(S34=0,P34*Q34*R34/10^6,P34*Q34*R34/10^6/S34) -> 0.010575
A35: =A34+1 -> 17 | B35: Pasang Isolator tarik 20 kV Polimer | E35: buah | I35: =SUM(F35:H35) -> 0 | K35: ='RAB Pasang'!K35*60% -> 41352 | L35: =J35*I35 -> 0 | M35: =K35*I35 -> 0 | N35: =SUM(L35:M35) -> 0 | P35: 73 | Q35: 17 | R35: 11 | S35: 0 | T35: =IF(S35=0,P35*Q35*R35/10^6,P35*Q35*R35/10^6/S35) -> 0.013651
A36: =A35+1 -> 18 | B36: Pasang Cut Out 20 kV | E36: buah | I36: =SUM(F36:H36) -> 0 | K36: ='RAB Pasang'!K36*60% -> 41352 | L36: =J36*I36 -> 0 | M36: =K36*I36 -> 0 | N36: =SUM(L36:M36) -> 0 | P36: 50 | Q36: 37 | R36: 14.5 | S36: 0 | T36: =IF(S36=0,P36*Q36*R36/10^6,P36*Q36*R36/10^6/S36) -> 0.026825
A37: =A36+1 -> 19 | B37: Pasang Lightning Arrester 24 kV | E37: buah | I37: =SUM(F37:H37) -> 0 | K37: ='RAB Pasang'!K37*60% -> 41352 | L37: =J37*I37 -> 0 | M37: =K37*I37 -> 0 | N37: =SUM(L37:M37) -> 0 | P37: 24 | Q37: 17 | R37: 26 | S37: 0 | T37: =IF(S37=0,P37*Q37*R37/10^6,P37*Q37*R37/10^6/S37) -> 0.010608
A38: =A37+1 -> 20 | B38: Pasang Trafo 3 phs 25 kVA - 20 kV | E38: buah | I38: =SUM(F38:H38) -> 0 | K38: ='RAB Pasang'!K38*60% -> 1064982 | L38: =J38*I38 -> 0 | M38: =K38*I38 -> 0 | N38: =SUM(L38:M38) -> 0 | P38: 76 | Q38: 51 | R38: 102 | S38: 0 | T38: =IF(S38=0,P38*Q38*R38/10^6,P38*Q38*R38/10^6/S38) -> 0.395352
A39: =A38+1 -> 21 | B39: Pasang Trafo 3 phs 50 kVA - 20 kV | E39: buah | I39: =SUM(F39:H39) -> 0 | K39: ='RAB Pasang'!K39*60% -> 1161228 | L39: =J39*I39 -> 0 | M39: =K39*I39 -> 0 | N39: =SUM(L39:M39) -> 0 | P39: 88 | Q39: 54 | R39: 111 | S39: 0 | T39: =IF(S39=0,P39*Q39*R39/10^6,P39*Q39*R39/10^6/S39) -> 0.527472
A40: =A39+1 -> 22 | B40: Pasang Trafo 3 phs 100 kVA - 20 kV | E40: buah | I40: =SUM(F40:H40) -> 0 | K40: ='RAB Pasang'!K40*60% -> 1305600 | L40: =J40*I40 -> 0 | M40: =K40*I40 -> 0 | N40: =SUM(L40:M40) -> 0 | P40: 96 | Q40: 65 | R40: 116 | S40: 0 | T40: =IF(S40=0,P40*Q40*R40/10^6,P40*Q40*R40/10^6/S40) -> 0.72384
A41: =A40+1 -> 23 | B41: Pasang Trafo 3 phs 160 kVA - 20 kV | E41: buah | I41: =SUM(F41:H41) -> 0 | K41: ='RAB Pasang'!K41*60% -> 1495020 | L41: =J41*I41 -> 0 | M41: =K41*I41 -> 0 | N41: =SUM(L41:M41) -> 0 | P41: 103 | Q41: 74 | R41: 128 | S41: 0 | T41: =IF(S41=0,P41*Q41*R41/10^6,P41*Q41*R41/10^6/S41) -> 0.975616
A42: =A41+1 -> 24 | B42: Pasang Trafo 3 phs 200 kVA - 20 kV | E42: buah | I42: =SUM(F42:H42) -> 0 | K42: ='RAB Pasang'!K42*60% -> 1830300 | L42: =J42*I42 -> 0 | M42: =K42*I42 -> 0 | N42: =SUM(L42:M42) -> 0 | P42: 107 | Q42: 81 | R42: 133 | S42: 0 | T42: =IF(S42=0,P42*Q42*R42/10^6,P42*Q42*R42/10^6/S42) -> 1.152711
A43: =A42+1 -> 25 | B43: Pasang Trafo 3 phs 250 kVA - 20 kV | E43: buah | I43: =SUM(F43:H43) -> 0 | K43: ='RAB Pasang'!K43*60% -> 1928880 | L43: =J43*I43 -> 0 | M43: =K43*I43 -> 0 | N43: =SUM(L43:M43) -> 0 | P43: 114 | Q43: 84 | R43: 136 | S43: 0 | T43: =IF(S43=0,P43*Q43*R43/10^6,P43*Q43*R43/10^6/S43) -> 1.302336
... A46: =A45+1 -> 28 | B46: Pasang Trafo 3 phs 1000 kVA - 20 kV | E46: buah | I46: =SUM(F46:H46) -> 0 | K46: ='RAB Pasang'!K46*60% -> 2216880 | L46: =J46*I46 -> 0 | M46: =K46*I46 -> 0 | N46: =SUM(L46:M46) -> 0 | P46: 166 | Q46: 112 | R46: 187 | S46: 0 | T46: =IF(S46=0,P46*Q46*R46/10^6,P46*Q46*R46/10^6/S46) -> 3.476704
A47: =A46+1 -> 29 | B47: Pasang Konduktor SUTM AAAC 3x35 mm² | E47: ms | I47: =SUM(F47:H47) -> 0 | K47: ='RAB Pasang'!K47*60% -> 3619.29 | L47: =J47*I47 -> 0 | M47: =K47*I47 -> 0 | N47: =SUM(L47:M47) -> 0 | P47: 145 | Q47: 145 | R47: 60 | S47: 3000 | T47: =IF(S47=0,P47*Q47*R47/10^6,P47*Q47*R47/10^6/S47) -> 0.0004205 | U47: Konversi satuan dan harga dari kms ke ms (KHS dalam kms)
A48: =A47+1 -> 30 | B48: Pasang Konduktor SUTM AAAC 3x50 mm² | E48: ms | I48: =SUM(F48:H48) -> 0 | K48: ='RAB Pasang'!K48*60% -> 4454.514 | L48: =J48*I48 -> 0 | M48: =K48*I48 -> 0 | N48: =SUM(L48:M48) -> 0 | P48: 145 | Q48: 145 | R48: 70 | S48: 3000 | T48: =IF(S48=0,P48*Q48*R48/10^6,P48*Q48*R48/10^6/S48) -> 0.00049058333 | U48: Konversi satuan dan harga dari kms ke ms (KHS dalam kms)
A49: =A48+1 -> 31 | B49: Pasang Konduktor SUTM AAAC 3x70 mm² | E49: ms | I49: =SUM(F49:H49) -> 0 | K49: ='RAB Pasang'!K49*60% -> 5264.424 | L49: =J49*I49 -> 0 | M49: =K49*I49 -> 0 | N49: =SUM(L49:M49) -> 0 | P49: 145 | Q49: 145 | R49: 85 | S49: 3000 | T49: =IF(S49=0,P49*Q49*R49/10^6,P49*Q49*R49/10^6/S49) -> 0.00059570833 | U49: Konversi satuan dan harga dari kms ke ms (KHS dalam kms)
A50: =A49+1 -> 32 | B50: Pasang Konduktor SUTM AAAC 3x95 mm² | E50: ms | I50: =SUM(F50:H50) -> 0 | K50: ='RAB Pasang'!K50*60% -> 6434.298 | L50: =J50*I50 -> 0 | M50: =K50*I50 -> 0 | N50: =SUM(L50:M50) -> 0 | P50: 145 | Q50: 145 | R50: 95 | S50: 2000 | T50: =IF(S50=0,P50*Q50*R50/10^6,P50*Q50*R50/10^6/S50) -> 0.0009986875 | U50: Konversi satuan dan harga dari kms ke ms (KHS dalam kms)
A51: =A50+1 -> 33 | B51: Pasang Konduktor SUTM AAAC 3x120 mm² | E51: ms | I51: =SUM(F51:H51) -> 0 | K51: ='RAB Pasang'!K51*60% -> 8272.668 | L51: =J51*I51 -> 0 | M51: =K51*I51 -> 0 | N51: =SUM(L51:M51) -> 0 | P51: 145 | Q51: 145 | R51: 100 | S51: 2000 | T51: =IF(S51=0,P51*Q51*R51/10^6,P51*Q51*R51/10^6/S51) -> 0.00105125 | U51: Konversi satuan dan harga dari kms ke ms (KHS dalam kms)
A52: =A51+1 -> 34 | B52: Pasang Konduktor SUTM AAAC 3x150 mm² | E52: ms | I52: =SUM(F52:H52) -> 0 | K52: ='RAB Pasang'!K52*60% -> 9651.444 | L52: =J52*I52 -> 0 | M52: =K52*I52 -> 0 | N52: =SUM(L52:M52) -> 0 | P52: 145 | Q52: 145 | R52: 110 | S52: 2000 | T52: =IF(S52=0,P52*Q52*R52/10^6,P52*Q52*R52/10^6/S52) -> 0.001156375 | U52: Konversi satuan dan harga dari kms ke ms (KHS dalam kms)
...

Sheet RAB Perbaikan
A4: RAB PEKERJAAN PEMBONGKARAN KONSTRUKSI JARINGAN DISTRIBUSI KUPANG - KHS 2026
A6: =REKAP!B8&REKAP!E8&REKAP!F8 -> NAMA PEKERJAAN : UNTUK LOKASI
A7: =REKAP!B9&REKAP!E9&REKAP!F9 -> UNIT : ULP KUPANG
A13: NO | B13: URAIAN MATERIAL / PEKERJAAN | E13: SATUAN | F13: VOLUME | J13: HARGA SATUAN | L13: HARGA BAGIAN | N13: JUMLAH HARGA | P13: Asumsi Ukuran | S13: Perkiraan Panjang | T13: Perkiraan Kubikasi
F14: JTM | G14: Gardu | H14: JTR | I14: Total | J14: BAHAN | K14: UPAH | L14: BAHAN | M14: UPAH | P14: P | Q14: L | R14: T
J15: (Rp) | K15: (Rp) | L15: (Rp) | M15: (Rp) | N15: (Rp) | P15: cm | Q15: cm | R15: cm | S15: m/haspel | T15: m3/item
A16: 1 | B16: 2 | E16: 3 | F16: 4 | G16: 5 | H16: 6 | I16: 7=4+5+6 | J16: 8 | K16: 9 | L16: 10=7x8 | M16: 11=7x9 | N16: 12=10+11 | P16: 13 | Q16: 14 | R16: 15 | S16: 16 | T16: 17=13x14x15/10^6/16
A18: A | B18: MATERIAL UTAMA (Disediakan PLN)
A19: 1 | B19: Mendirikan Tiang Beton 9 meter 200 daN | E19: batang | I19: =SUM(F19:H19) -> 0 | K19: ='RAB Pasang'!K19*40% -> 447128 | L19: =J19*I19 -> 0 | M19: =K19*I19 -> 0 | N19: =SUM(L19:M19) -> 0
A20: =A19+1 -> 2 | B20: Mendirikan Tiang Beton 12 meter 200 daN | E20: batang | I20: =SUM(F20:H20) -> 0 | K20: ='RAB Pasang'!K20*40% -> 639124 | L20: =J20*I20 -> 0 | M20: =K20*I20 -> 0 | N20: =SUM(L20:M20) -> 0
A21: =A20+1 -> 3 | B21: Mendirikan Tiang Beton 12 meter 350 daN | E21: batang | I21: =SUM(F21:H21) -> 0 | K21: ='RAB Pasang'!K21*40% -> 735124 | L21: =J21*I21 -> 0 | M21: =K21*I21 -> 0 | N21: =SUM(L21:M21) -> 0
A22: =A21+1 -> 4 | B22: Mendirikan Tiang Beton 13 meter 350 daN | E22: batang | I22: =SUM(F22:H22) -> 0 | K22: ='RAB Pasang'!K22*40% -> 852164 | L22: =J22*I22 -> 0 | M22: =K22*I22 -> 0 | N22: =SUM(L22:M22) -> 0
A23: =A22+1 -> 5 | B23: Mendirikan Tiang Beton 14 meter 350 daN | E23: batang | I23: =SUM(F23:H23) -> 0 | K23: ='RAB Pasang'!K23*40% -> 1278248 | L23: =J23*I23 -> 0 | M23: =K23*I23 -> 0 | N23: =SUM(L23:M23) -> 0
A24: =A23+1 -> 6 | B24: Mendirikan Tiang Baja 7 meter 100 daN | E24: batang | I24: =SUM(F24:H24) -> 0 | K24: ='RAB Pasang'!K24*40% -> 179884 | L24: =J24*I24 -> 0 | M24: =K24*I24 -> 0 | N24: =SUM(L24:M24) -> 0
A25: =A24+1 -> 7 | B25: Mendirikan Tiang Baja 9 meter 100 daN | E25: batang | I25: =SUM(F25:H25) -> 0 | K25: ='RAB Pasang'!K25*40% -> 284056 | L25: =J25*I25 -> 0 | M25: =K25*I25 -> 0 | N25: =SUM(L25:M25) -> 0
A26: =A25+1 -> 8 | B26: Mendirikan Tiang Baja 9 meter 200 daN | E26: batang | I26: =SUM(F26:H26) -> 0 | K26: ='RAB Pasang'!K26*40% -> 340180 | L26: =J26*I26 -> 0 | M26: =K26*I26 -> 0 | N26: =SUM(L26:M26) -> 0
A27: =A26+1 -> 9 | B27: Mendirikan Tiang Baja 11 meter 200 daN | E27: batang | I27: =SUM(F27:H27) -> 0 | K27: ='RAB Pasang'!K27*40% -> 398488 | L27: =J27*I27 -> 0 | M27: =K27*I27 -> 0 | N27: =SUM(L27:M27) -> 0
A28: =A27+1 -> 10 | B28: Mendirikan Tiang Baja 12 meter 200 daN | E28: batang | I28: =SUM(F28:H28) -> 0 | K28: ='RAB Pasang'!K28*40% -> 455412 | L28: =J28*I28 -> 0 | M28: =K28*I28 -> 0 | N28: =SUM(L28:M28) -> 0
A29: =A28+1 -> 11 | B29: Mendirikan Tiang Baja 12 meter 350 daN | E29: batang | I29: =SUM(F29:H29) -> 0 | K29: ='RAB Pasang'!K29*40% -> 531316 | L29: =J29*I29 -> 0 | M29: =K29*I29 -> 0 | N29: =SUM(L29:M29) -> 0
A30: =A29+1 -> 12 | B30: Mendirikan Tiang Baja 13 meter 350 daN | E30: batang | I30: =SUM(F30:H30) -> 0 | K30: ='RAB Pasang'!K30*40% -> 637580 | L30: =J30*I30 -> 0 | M30: =K30*I30 -> 0 | N30: =SUM(L30:M30) -> 0
A31: =A30+1 -> 13 | B31: Mendirikan Tiang Baja 14 meter 350 daN | E31: batang | I31: =SUM(F31:H31) -> 0 | K31: ='RAB Pasang'!K31*40% -> 702264 | L31: =J31*I31 -> 0 | M31: =K31*I31 -> 0 | N31: =SUM(L31:M31) -> 0
A32: =A31+1 -> 14 | B32: Pasang Isolator tumpu 20 kV Porcelin | E32: buah | I32: =SUM(F32:H32) -> 0 | K32: ='RAB Pasang'!K32*40% -> 27568 | L32: =J32*I32 -> 0 | M32: =K32*I32 -> 0 | N32: =SUM(L32:M32) -> 0 | P32: 15 | Q32: 15 | R32: 47 | S32: 0 | T32: =IF(S32=0,P32*Q32*R32/10^6,P32*Q32*R32/10^6/S32) -> 0.010575
A33: =A32+1 -> 15 | B33: Pasang Isolator tarik 20 kV Porcelin | E33: buah | I33: =SUM(F33:H33) -> 0 | K33: ='RAB Pasang'!K33*40% -> 30324 | L33: =J33*I33 -> 0 | M33: =K33*I33 -> 0 | N33: =SUM(L33:M33) -> 0 | P33: 30 | Q33: 25.4 | R33: 25.4 | S33: 0 | T33: =IF(S33=0,P33*Q33*R33/10^6,P33*Q33*R33/10^6/S33) -> 0.0193548
A34: =A33+1 -> 16 | B34: Pasang Isolator tumpu 20 kV Polimer | E34: buah | I34: =SUM(F34:H34) -> 0 | K34: ='RAB Pasang'!K34*40% -> 25272 | L34: =J34*I34 -> 0 | M34: =K34*I34 -> 0 | N34: =SUM(L34:M34) -> 0 | P34: 15 | Q34: 15 | R34: 47 | S34: 0 | T34: =IF(S34=0,P34*Q34*R34/10^6,P34*Q34*R34/10^6/S34) -> 0.010575
A35: =A34+1 -> 17 | B35: Pasang Isolator tarik 20 kV Polimer | E35: buah | I35: =SUM(F35:H35) -> 0 | K35: ='RAB Pasang'!K35*40% -> 27568 | L35: =J35*I35 -> 0 | M35: =K35*I35 -> 0 | N35: =SUM(L35:M35) -> 0 | P35: 73 | Q35: 17 | R35: 11 | S35: 0 | T35: =IF(S35=0,P35*Q35*R35/10^6,P35*Q35*R35/10^6/S35) -> 0.013651
A36: =A35+1 -> 18 | B36: Pasang Cut Out 20 kV | E36: buah | I36: =SUM(F36:H36) -> 0 | K36: ='RAB Pasang'!K36*40% -> 27568 | L36: =J36*I36 -> 0 | M36: =K36*I36 -> 0 | N36: =SUM(L36:M36) -> 0 | P36: 50 | Q36: 37 | R36: 14.5 | S36: 0 | T36: =IF(S36=0,P36*Q36*R36/10^6,P36*Q36*R36/10^6/S36) -> 0.026825
A37: =A36+1 -> 19 | B37: Pasang Lightning Arrester 24 kV | E37: buah | I37: =SUM(F37:H37) -> 0 | K37: ='RAB Pasang'!K37*40% -> 27568 | L37: =J37*I37 -> 0 | M37: =K37*I37 -> 0 | N37: =SUM(L37:M37) -> 0 | P37: 24 | Q37: 17 | R37: 26 | S37: 0 | T37: =IF(S37=0,P37*Q37*R37/10^6,P37*Q37*R37/10^6/S37) -> 0.010608
A38: =A37+1 -> 20 | B38: Pasang Trafo 3 phs 25 kVA - 20 kV | E38: buah | I38: =SUM(F38:H38) -> 0 | K38: ='RAB Pasang'!K38*40% -> 709988 | L38: =J38*I38 -> 0 | M38: =K38*I38 -> 0 | N38: =SUM(L38:M38) -> 0 | P38: 76 | Q38: 51 | R38: 102 | S38: 0 | T38: =IF(S38=0,P38*Q38*R38/10^6,P38*Q38*R38/10^6/S38) -> 0.395352
A39: =A38+1 -> 21 | B39: Pasang Trafo 3 phs 50 kVA - 20 kV | E39: buah | I39: =SUM(F39:H39) -> 0 | K39: ='RAB Pasang'!K39*40% -> 774152 | L39: =J39*I39 -> 0 | M39: =K39*I39 -> 0 | N39: =SUM(L39:M39) -> 0 | P39: 88 | Q39: 54 | R39: 111 | S39: 0 | T39: =IF(S39=0,P39*Q39*R39/10^6,P39*Q39*R39/10^6/S39) -> 0.527472
A40: =A39+1 -> 22 | B40: Pasang Trafo 3 phs 100 kVA - 20 kV | E40: buah | I40: =SUM(F40:H40) -> 0 | K40: ='RAB Pasang'!K40*40% -> 870400 | L40: =J40*I40 -> 0 | M40: =K40*I40 -> 0 | N40: =SUM(L40:M40) -> 0 | P40: 96 | Q40: 65 | R40: 116 | S40: 0 | T40: =IF(S40=0,P40*Q40*R40/10^6,P40*Q40*R40/10^6/S40) -> 0.72384
A41: =A40+1 -> 23 | B41: Pasang Trafo 3 phs 160 kVA - 20 kV | E41: buah | I41: =SUM(F41:H41) -> 0 | K41: ='RAB Pasang'!K41*40% -> 996680 | L41: =J41*I41 -> 0 | M41: =K41*I41 -> 0 | N41: =SUM(L41:M41) -> 0 | P41: 103 | Q41: 74 | R41: 128 | S41: 0 | T41: =IF(S41=0,P41*Q41*R41/10^6,P41*Q41*R41/10^6/S41) -> 0.975616
A42: =A41+1 -> 24 | B42: Pasang Trafo 3 phs 200 kVA - 20 kV | E42: buah | I42: =SUM(F42:H42) -> 0 | K42: ='RAB Pasang'!K42*40% -> 1220200 | L42: =J42*I42 -> 0 | M42: =K42*I42 -> 0 | N42: =SUM(L42:M42) -> 0 | P42: 107 | Q42: 81 | R42: 133 | S42: 0 | T42: =IF(S42=0,P42*Q42*R42/10^6,P42*Q42*R42/10^6/S42) -> 1.152711
A43: =A42+1 -> 25 | B43: Pasang Trafo 3 phs 250 kVA - 20 kV | E43: buah | I43: =SUM(F43:H43) -> 0 | K43: ='RAB Pasang'!K43*40% -> 1285920 | L43: =J43*I43 -> 0 | M43: =K43*I43 -> 0 | N43: =SUM(L43:M43) -> 0 | P43: 114 | Q43: 84 | R43: 136 | S43: 0 | T43: =IF(S43=0,P43*Q43*R43/10^6,P43*Q43*R43/10^6/S43) -> 1.302336
... A46: =A45+1 -> 28 | B46: Pasang Trafo 3 phs 1000 kVA - 20 kV | E46: buah | I46: =SUM(F46:H46) -> 0 | K46: ='RAB Pasang'!K46*40% -> 1477920 | L46: =J46*I46 -> 0 | M46: =K46*I46 -> 0 | N46: =SUM(L46:M46) -> 0 | P46: 166 | Q46: 112 | R46: 187 | S46: 0 | T46: =IF(S46=0,P46*Q46*R46/10^6,P46*Q46*R46/10^6/S46) -> 3.476704
A47: =A46+1 -> 29 | B47: Pasang Konduktor SUTM AAAC 3x35 mm² | E47: ms | I47: =SUM(F47:H47) -> 0 | K47: ='RAB Pasang'!K47*40% -> 2412.86 | L47: =J47*I47 -> 0 | M47: =K47*I47 -> 0 | N47: =SUM(L47:M47) -> 0 | P47: 145 | Q47: 145 | R47: 60 | S47: 3000 | T47: =IF(S47=0,P47*Q47*R47/10^6,P47*Q47*R47/10^6/S47) -> 0.0004205 | U47: Konversi satuan dan harga dari kms ke ms (KHS dalam kms)
A48: =A47+1 -> 30 | B48: Pasang Konduktor SUTM AAAC 3x50 mm² | E48: ms | I48: =SUM(F48:H48) -> 0 | K48: ='RAB Pasang'!K48*40% -> 2969.676 | L48: =J48*I48 -> 0 | M48: =K48*I48 -> 0 | N48: =SUM(L48:M48) -> 0 | P48: 145 | Q48: 145 | R48: 70 | S48: 3000 | T48: =IF(S48=0,P48*Q48*R48/10^6,P48*Q48*R48/10^6/S48) -> 0.00049058333 | U48: Konversi satuan dan harga dari kms ke ms (KHS dalam kms)
A49: =A48+1 -> 31 | B49: Pasang Konduktor SUTM AAAC 3x70 mm² | E49: ms | I49: =SUM(F49:H49) -> 0 | K49: ='RAB Pasang'!K49*40% -> 3509.616 | L49: =J49*I49 -> 0 | M49: =K49*I49 -> 0 | N49: =SUM(L49:M49) -> 0 | P49: 145 | Q49: 145 | R49: 85 | S49: 3000 | T49: =IF(S49=0,P49*Q49*R49/10^6,P49*Q49*R49/10^6/S49) -> 0.00059570833 | U49: Konversi satuan dan harga dari kms ke ms (KHS dalam kms)
A50: =A49+1 -> 32 | B50: Pasang Konduktor SUTM AAAC 3x95 mm² | E50: ms | I50: =SUM(F50:H50) -> 0 | K50: ='RAB Pasang'!K50*40% -> 4289.532 | L50: =J50*I50 -> 0 | M50: =K50*I50 -> 0 | N50: =SUM(L50:M50) -> 0 | P50: 145 | Q50: 145 | R50: 95 | S50: 2000 | T50: =IF(S50=0,P50*Q50*R50/10^6,P50*Q50*R50/10^6/S50) -> 0.0009986875 | U50: Konversi satuan dan harga dari kms ke ms (KHS dalam kms)
A51: =A50+1 -> 33 | B51: Pasang Konduktor SUTM AAAC 3x120 mm² | E51: ms | I51: =SUM(F51:H51) -> 0 | K51: ='RAB Pasang'!K51*40% -> 5515.112 | L51: =J51*I51 -> 0 | M51: =K51*I51 -> 0 | N51: =SUM(L51:M51) -> 0 | P51: 145 | Q51: 145 | R51: 100 | S51: 2000 | T51: =IF(S51=0,P51*Q51*R51/10^6,P51*Q51*R51/10^6/S51) -> 0.00105125 | U51: Konversi satuan dan harga dari kms ke ms (KHS dalam kms)
A52: =A51+1 -> 34 | B52: Pasang Konduktor SUTM AAAC 3x150 mm² | E52: ms | I52: =SUM(F52:H52) -> 0 | K52: ='RAB Pasang'!K52*40% -> 6434.296 | L52: =J52*I52 -> 0 | M52: =K52*I52 -> 0 | N52: =SUM(L52:M52) -> 0 | P52: 145 | Q52: 145 | R52: 110 | S52: 2000 | T52: =IF(S52=0,P52*Q52*R52/10^6,P52*Q52*R52/10^6/S52) -> 0.001156375 | U52: Konversi satuan dan harga dari kms ke ms (KHS dalam kms)
...

Sheet D1 Tiang
A1: ANALISA HARGA SATUAN MATERIAL KONSTRUKSI
A2: STAY EQUIPMENT (SKUR)
J3: ROK | K3: 0.15
A4: No | B4: Uraian | H4: Satuan | I4: Volume | J4: Harga (Rp)
J5: Dasar | K5: Harga Satuan
A7: 1 | B7: 1 Set | D7: Perlengkapan Drukschoor Tiang Beton 9 mtr / 200 daN
B8: 1) | C8: Pole band galv. 1/2, Ø 6,5" (pemegang UNP) | H8: buah | I8: 1 | J8: ='Harga Satuan Dasar mat'!G22 -> 95500 | K8: =I8*J8 -> 95500
B9: 2) | C9: Single Fixing Collar / GW Band 2/2 ; Ø 7" (atas tiang penumpu) | H9: buah | I9: 1 | J9: ='Harga Satuan Dasar mat'!G75 -> 164250 | K9: =I9*J9 -> 164250
B10: 3) | C10: Single Fixing Collar / GW Band 2/2 ; Ø 6,5" (atas tiang topang) | H10: buah | I10: 1 | J10: ='Harga Satuan Dasar mat'!G74 -> 156000 | K10: =I10*J10 -> 156000
B11: 4) | C11: Single Fixing Collar / GW Band 2/2 ; Ø 9" (tengah tiang lurus) | H11: buah | I11: 1 | J11: ='Harga Satuan Dasar mat'!G79 -> 196500 | K11: =I11*J11 -> 196500
B12: 5) | C12: Single Fixing Collar / GW Band 2/2 ; Ø 8,5" (tengah tiang topang) | H12: buah | I12: 1 | J12: ='Harga Satuan Dasar mat'!G78 -> 189500 | K12: =I12*J12 -> 189500
B13: 6) | C13: Pipa Galvanise Diameter 2" Panjang 1500mm (untuk JTR) | H13: batang | I13: 1 | J13: ='Harga Satuan Dasar mat'!G301 -> 253000 | K13: =I13*J13 -> 253000
B14: 7) | C14: Besi UNP 100 (100mm x 50mm x 5mm) Panjang 200mm HDG | H14: batang | I14: 1 | J14: ='Harga Satuan Dasar mat'!G159 -> 95000 | K14: =I14*J14 -> 95000
B15: 8) | C15: Bolt & nut 5/8 x 50 + ring + 2 mur (galvanis) - M16 | H15: buah | I15: 13 | J15: ='Harga Satuan Dasar mat'!G252 -> 14000 | K15: =I15*J15 -> 182000
H16: Jumlah | K16: =SUM(K8:K15) -> 1331750
H17: ROK | I17: =$K$3 -> 0.15 | K17: =I17*K16 -> 199762.5
H18: Total | K18: =SUM(K16:K17) -> 1531512.5
H19: Pembulatan | K19: =ROUND(K18,-1) -> 1531510
A20: 2 | B20: 1 Set | D20: Perlengkapan Drukschoor Tiang Beton 12 mtr / 200 daN & Tiang Beton 12 mtr / 350 daN
B21: 1) | C21: Pole band galv. 1/2, Ø 8" (pemegang UNP) | H21: buah | I21: 1 | J21: ='Harga Satuan Dasar mat'!G25 -> 110000 | K21: =I21*J21 -> 110000
B22: 2) | C22: Single Fixing Collar / GW Band 2/2 ; Ø 8,5" (atas tiang penumpu) | H22: buah | I22: 1 | J22: =J12 -> 189500 | K22: =I22*J22 -> 189500
B23: 3) | C23: Single Fixing Collar / GW Band 2/2 ; Ø 8" (atas tiang topang) | H23: buah | I23: 1 | J23: ='Harga Satuan Dasar mat'!G77 -> 181000 | K23: =I23*J23 -> 181000
B24: 4) | C24: Single Fixing Collar / GW Band 2/2 ; Ø 11,5" (tengah tiang lurus) | H24: buah | I24: 1 | J24: ='Harga Satuan Dasar mat'!G84 -> 239000 | K24: =I24*J24 -> 239000
B25: 5) | C25: Single Fixing Collar / GW Band 2/2 ; Ø 11" (tengah tiang topang) | H25: buah | I25: 1 | J25: ='Harga Satuan Dasar mat'!G83 -> 231500 | K25: =I25*J25 -> 231500
B26: 6) | C26: Pipa Galvanise Diameter 3" Panjang 2000mm | H26: batang | I26: 1 | J26: ='Harga Satuan Dasar mat'!G322 -> 454000 | K26: =I26*J26 -> 454000
B27: 7) | C27: Besi UNP 100 (100mm x 50mm x 5mm) Panjang 200mm HDG | H27: batang | I27: 1 | J27: =J14 -> 95000 | K27: =I27*J27 -> 95000
B28: 8) | C28: Bolt & nut 5/8 x 50 + ring + 2 mur (galvanis) - M16 | H28: buah | I28: 13 | J28: =J15 -> 14000 | K28: =I28*J28 -> 182000
H29: Jumlah | K29: =SUM(K21:K28) -> 1682000
H30: ROK | I30: =$K$3 -> 0.15 | K30: =I30*K29 -> 252300
H31: Total | K31: =SUM(K29:K30) -> 1934300
H32: Pembulatan | K32: =ROUND(K31,-1) -> 1934300
A33: 3 | B33: 1 Set | D33: Perlengkapan Drukschoor Tiang Beton 13 mtr / 350 daN & Tiang Beton 14 mtr / 350 daN
B34: 1) | C34: Pole band galv. 1/2, Ø 8" (pemegang UNP) | H34: buah | I34: 1 | J34: =J21 -> 110000 | K34: =I34*J34 -> 110000
B35: 2) | C35: Single Fixing Collar / GW Band 2/2 ; Ø 8,5" (atas tiang penumpu) | H35: buah | I35: 1 | J35: =J22 -> 189500 | K35: =I35*J35 -> 189500
B36: 3) | C36: Single Fixing Collar / GW Band 2/2 ; Ø 8" (atas tiang topang) | H36: buah | I36: 1 | J36: =J23 -> 181000 | K36: =I36*J36 -> 181000
B37: 4) | C37: Single Fixing Collar / GW Band 2/2 ; Ø 11,5" (tengah tiang lurus) | H37: buah | I37: 1 | J37: =J24 -> 239000 | K37: =I37*J37 -> 239000
B38: 5) | C38: Single Fixing Collar / GW Band 2/2 ; Ø 11" (tengah tiang topang) | H38: buah | I38: 1 | J38: =J25 -> 231500 | K38: =I38*J38 -> 231500
B39: 6) | C39: Pipa Galvanise Diameter 3" Panjang 2000mm | H39: batang | I39: 1 | J39: =J26 -> 454000 | K39: =I39*J39 -> 454000
B40: 7) | C40: Besi UNP 100 (100mm x 50mm x 5mm) Panjang 200mm HDG | H40: batang | I40: 1 | J40: =J27 -> 95000 | K40: =I40*J40 -> 95000
B41: 8) | C41: Bolt & nut 5/8 x 50 + ring + 2 mur (galvanis) - M16 | H41: buah | I41: 13 | J41: =J28 -> 14000 | K41: =I41*J41 -> 182000
...

Sheet D2 SUTM
A1: ANALISA HARGA SATUAN MATERIAL KONSTRUKSI
A2: SALURAN UDARA TEGANGAN MENENGAH (SUTM)
J3: ROK | K3: 0.15
A4: No | B4: Uraian | H4: Satuan | I4: Volume | J4: Harga (Rp)
J5: Dasar | K5: Harga Satuan
A7: 1 | B7: 1 Set | D7: Cross Arm Type A1 UNP 100 Balance - Tiang Beton 14/350, 13/350, 12/350 & 12/200
B8: 1) | C8: Besi UNP 100 (100mm x 50mm x 5mm) Panjang 2000mm HDG | H8: batang | I8: 1 | J8: ='Harga Satuan Dasar mat'!G147 -> 800000 | K8: =I8*J8 -> 800000
B9: 2) | C9: Pole band 1/2 (Clamp Begel U) Ø 7,5" HDG | H9: buah | I9: 1 | J9: ='Harga Satuan Dasar mat'!G24 -> 105500 | K9: =I9*J9 -> 105500
B10: 3) | C10: Single Fixing Collar / GW Band 2/2 ; Ø 8" HDG | H10: buah | I10: 1 | J10: ='Harga Satuan Dasar mat'!G77 -> 181000 | K10: =I10*J10 -> 181000
B11: 4) | C11: Arm tie galvanise (Besi Siku/Besi L 50mm x 50mm x 5mm) Panjang 1270 mm | H11: batang | I11: 1 | J11: ='Harga Satuan Dasar mat'!G203 -> 283250 | K11: =I11*J11 -> 283250
B12: 5) | C12: Steel Plate type II (6 mm x 100 mm x 120 mm) | H12: buah | I12: 2 | J12: ='Harga Satuan Dasar mat'!G416 -> 33500 | K12: =I12*J12 -> 67000
B13: 6) | C13: Bolt & nut 5/8 x 50 + ring + 2 mur (galvanis) - M16 | H13: buah | I13: 5 | J13: ='Harga Satuan Dasar mat'!G252 -> 14000 | K13: =I13*J13 -> 70000
B14: 7) | C14: Bolt & nut 5/8 x 140 + ring + 2 mur (galvanis) - M16 | H14: buah | I14: 2 | J14: ='Harga Satuan Dasar mat'!G248 -> 27000 | K14: =I14*J14 -> 54000
H15: Jumlah | K15: =SUM(K8:K14) -> 1560750
H16: ROK | I16: =$K$3 -> 0.15 | K16: =I16*K15 -> 234112.5
H17: Total | K17: =SUM(K15:K16) -> 1794862.5
H18: Pembulatan | K18: =ROUND(K17,-1) -> 1794860
A19: 2 | B19: 1 Set | D19: Cross Arm Type A1 UNP 100 Balance - Tiang Baja 14/350
B20: 1) | C20: Besi UNP 100 (100mm x 50mm x 5mm) Panjang 2000mm HDG | H20: batang | I20: 1 | J20: =J8 -> 800000 | K20: =I20*J20 -> 800000
B21: 2) | C21: Pole band 1/2 (Clamp Begel U) Ø 8,5" HDG | H21: buah | I21: 1 | J21: ='Harga Satuan Dasar mat'!G26 -> 115000 | K21: =I21*J21 -> 115000
B22: 3) | C22: Single Fixing Collar / GW Band 2/2 ; Ø 8,5" HDG | H22: buah | I22: 1 | J22: ='Harga Satuan Dasar mat'!G78 -> 189500 | K22: =I22*J22 -> 189500
B23: 4) | C23: Arm tie galvanise (Besi Siku/Besi L 50mm x 50mm x 5mm) Panjang 1270 mm | H23: batang | I23: 1 | J23: =J11 -> 283250 | K23: =I23*J23 -> 283250
B24: 5) | C24: Steel Plate type II (6 mm x 100 mm x 120 mm) | H24: buah | I24: 2 | J24: =J12 -> 33500 | K24: =I24*J24 -> 67000
B25: 6) | C25: Bolt & nut 5/8 x 50 + ring + 2 mur (galvanis) - M16 | H25: buah | I25: 5 | J25: =J13 -> 14000 | K25: =I25*J25 -> 70000
B26: 7) | C26: Bolt & nut 5/8 x 140 + ring + 2 mur (galvanis) - M16 | H26: buah | I26: 2 | J26: =J14 -> 27000 | K26: =I26*J26 -> 54000
H27: Jumlah | K27: =SUM(K20:K26) -> 1578750
H28: ROK | I28: =$K$3 -> 0.15 | K28: =I28*K27 -> 236812.5
H29: Total | K29: =SUM(K27:K28) -> 1815562.5
H30: Pembulatan | K30: =ROUND(K29,-1) -> 1815560
A31: 3 | B31: 1 Set | D31: Cross Arm Type A1 UNP 100 Balance - Tiang Baja 13/350 & Tiang Baja 12/350
B32: 1) | C32: Besi UNP 100 (100mm x 50mm x 5mm) Panjang 2000mm HDG | H32: batang | I32: 1 | J32: =J20 -> 800000 | K32: =I32*J32 -> 800000
B33: 2) | C33: Pole band 1/2 (Clamp Begel U) Ø 6,5" HDG | H33: buah | I33: 1 | J33: ='Harga Satuan Dasar mat'!G22 -> 95500 | K33: =I33*J33 -> 95500
B34: 3) | C34: Single Fixing Collar / GW Band 2/2 ; Ø 6,5" HDG | H34: buah | I34: 1 | J34: ='Harga Satuan Dasar mat'!G74 -> 156000 | K34: =I34*J34 -> 156000
B35: 4) | C35: Arm tie galvanise (Besi Siku/Besi L 50mm x 50mm x 5mm) Panjang 1270 mm | H35: batang | I35: 1 | J35: =J23 -> 283250 | K35: =I35*J35 -> 283250
B36: 5) | C36: Steel Plate type II (6 mm x 100 mm x 120 mm) | H36: buah | I36: 2 | J36: =J24 -> 33500 | K36: =I36*J36 -> 67000
B37: 6) | C37: Bolt & nut 5/8 x 50 + ring + 2 mur (galvanis) - M16 | H37: buah | I37: 5 | J37: =J25 -> 14000 | K37: =I37*J37 -> 70000
B38: 7) | C38: Bolt & nut 5/8 x 140 + ring + 2 mur (galvanis) - M16 | H38: buah | I38: 2 | J38: =J26 -> 27000 | K38: =I38*J38 -> 54000
H39: Jumlah | K39: =SUM(K32:K38) -> 1525750
H40: ROK | I40: =$K$3 -> 0.15 | K40: =I40*K39 -> 228862.5
H41: Total | K41: =SUM(K39:K40) -> 1754612.5
...

Sheet D3 SKUTM
A1: ANALISA HARGA SATUAN MATERIAL KONSTRUKSI
A2: SALURAN KABEL UDATA TEGANGAN MENENGAH (SKUTM)
J3: ROK | K3: 0.15
A4: No | B4: Uraian | H4: Satuan | I4: Volume | J4: Harga (Rp)
J5: Dasar | K5: Harga Satuan
A7: 1 | B7: 1 Set | D7: Suspension Assembly JTM MVTIC Tiang Beton 14/350, Tiang Beton 13/350, Tiang Beton 12/350, Tiang Beton 12/200
B8: 1) | C8: Double Arm Fixing Collar 2/2 ; tebal 6mm x lebar 42mm, Ø 7,5" HDG | H8: buah | I8: 1 | J8: ='Harga Satuan Dasar mat'!G102 -> 203000 | K8: =I8*J8 -> 203000
B9: 2) | C9: Bolt & nut 5/8 x 50 + ring + 2 mur (galvanis) - M16 | H9: buah | I9: 4 | J9: ='Harga Satuan Dasar mat'!G252 -> 14000 | K9: =I9*J9 -> 56000
B10: 3) | C10: Separator Clamp for neutral | H10: buah | I10: 1 | J10: ='Harga Satuan Dasar mat'!G709 -> 74500 | K10: =I10*J10 -> 74500
H11: Jumlah | K11: =SUM(K8:K10) -> 333500
H12: ROK | I12: =$K$3 -> 0.15 | K12: =I12*K11 -> 50025
H13: Total | K13: =SUM(K11:K12) -> 383525
H14: Pembulatan | K14: =ROUND(K13,-1) -> 383530
A15: 2 | B15: 1 Set | D15: Suspension Assembly JTM MVTIC Tiang Baja 14/350
B16: 1) | C16: Double Arm Fixing Collar 2/2 ; tebal 6mm x lebar 42mm, Ø 8,5" HDG | H16: buah | I16: 1 | J16: ='Harga Satuan Dasar mat'!G104 -> 221500 | K16: =I16*J16 -> 221500
B17: 2) | C17: Bolt & nut 5/8 x 50 + ring + 2 mur (galvanis) - M16 | H17: buah | I17: 4 | J17: =J9 -> 14000 | K17: =I17*J17 -> 56000
B18: 3) | C18: Separator Clamp for neutral | H18: buah | I18: 1 | J18: =J10 -> 74500 | K18: =I18*J18 -> 74500
H19: Jumlah | K19: =SUM(K16:K18) -> 352000
H20: ROK | I20: =$K$3 -> 0.15 | K20: =I20*K19 -> 52800
H21: Total | K21: =SUM(K19:K20) -> 404800
H22: Pembulatan | K22: =ROUND(K21,-1) -> 404800
A23: 3 | B23: 1 Set | D23: Suspension Assembly JTM MVTIC Tiang Baja 13/350, Tiang Baja 12/350
B24: 1) | C24: Double Arm Fixing Collar 2/2 ; tebal 6mm x lebar 42mm, Ø 6,5" HDG | H24: buah | I24: 1 | J24: ='Harga Satuan Dasar mat'!G100 -> 184000 | K24: =I24*J24 -> 184000
B25: 2) | C25: Bolt & nut 5/8 x 50 + ring + 2 mur (galvanis) - M16 | H25: buah | I25: 4 | J25: =J17 -> 14000 | K25: =I25*J25 -> 56000
B26: 3) | C26: Separator Clamp for neutral | H26: buah | I26: 1 | J26: =J18 -> 74500 | K26: =I26*J26 -> 74500
H27: Jumlah | K27: =SUM(K24:K26) -> 314500
H28: ROK | I28: =$K$3 -> 0.15 | K28: =I28*K27 -> 47175
H29: Total | K29: =SUM(K27:K28) -> 361675
H30: Pembulatan | K30: =ROUND(K29,-1) -> 361680
A31: 4 | B31: 1 Set | D31: Suspension Assembly JTM MVTIC Tiang Baja 12/200
B32: 1) | C32: Double Arm Fixing Collar 2/2 ; tebal 6mm x lebar 42mm, Ø 5,5" HDG | H32: buah | I32: 1 | J32: ='Harga Satuan Dasar mat'!G98 -> 164500 | K32: =I32*J32 -> 164500
B33: 2) | C33: Bolt & nut 5/8 x 50 + ring + 2 mur (galvanis) - M16 | H33: buah | I33: 4 | J33: =J25 -> 14000 | K33: =I33*J33 -> 56000
B34: 3) | C34: Separator Clamp for neutral | H34: buah | I34: 1 | J34: =J26 -> 74500 | K34: =I34*J34 -> 74500
H35: Jumlah | K35: =SUM(K32:K34) -> 295000
H36: ROK | I36: =$K$3 -> 0.15 | K36: =I36*K35 -> 44250
H37: Total | K37: =SUM(K35:K36) -> 339250
H38: Pembulatan | K38: =ROUND(K37,-1) -> 339250
A39: 5 | B39: 1 Set | D39: Large Angle Assembly JTM MVTIC 95mm² Tiang Beton 14/350, Tiang Beton 13/350, Tiang Beton 12/350, Tiang Beton 12/200
B40: 1) | C40: Double Arm Fixing Collar 2/2 ; tebal 6mm x lebar 42mm, Ø 7,5" HDG | H40: buah | I40: 1 | J40: ='Harga Satuan Dasar mat'!G102 -> 203000 | K40: =I40*J40 -> 203000
B41: 2) | C41: Eye Nut M16 | H41: buah | I41: 2 | J41: ='Harga Satuan Dasar mat'!G737 -> 27550 | K41: =I41*J41 -> 55100
...

Sheet D4 SKTM
A1: ANALISA HARGA SATUAN MATERIAL KONSTRUKSI
A2: SALURAN KABEL TANAH TEGANGAN MENENGAH (SKTM)
J3: ROK | K3: 0.15
A4: No | B4: Uraian | H4: Satuan | I4: Volume | J4: Harga (Rp)
J5: Dasar | K5: Harga Satuan
A7: 1 | B7: 1 Set | D7: Asesoris Riser Pole (Tiang Awal/Kabel Naik) SKTM 95mm² - Tiang Beton
B8: 1) | C8: Pipa Besi Galvanised diameter 4,0" tebal minimal 2,5mm Panjang 6000mm | H8: batang | I8: 1 | J8: ='Harga Satuan Dasar mat'!G335 -> 1998000 | K8: =I8*J8 -> 1998000
B9: 2) | C9: Ornament Cable Band HDG 4 x 8" (pemegang Kabel) | H9: buah | I9: 1 | J9: ='Harga Satuan Dasar mat'!G481 -> 165000 | K9: =I9*J9 -> 165000
B10: 3) | C10: Ornament Cable Band HDG 4 x 10,5" (pemegang Pipa sisi atas ) | H10: buah | I10: 1 | J10: ='Harga Satuan Dasar mat'!G486 -> 182000 | K10: =I10*J10 -> 182000
B11: 4) | C11: Ornament Cable Band HDG 4 x 11,5" (pemegang Pipa sisi tengah) | H11: buah | I11: 1 | J11: ='Harga Satuan Dasar mat'!G488 -> 196000 | K11: =I11*J11 -> 196000
B12: 5) | C12: Ornament Cable Band HDG 4 x 13" (pemegang Pipa sisi bawah) | H12: buah | I12: 1 | J12: ='Harga Satuan Dasar mat'!G491 -> 240000 | K12: =I12*J12 -> 240000
B13: 6) | C13: Bolt & Nut 5/8"x70 mm + Washer Galvanis | H13: buah | I13: 12 | J13: ='Harga Satuan Dasar mat'!G251 -> 17000 | K13: =I13*J13 -> 204000
H14: Jumlah | K14: =SUM(K8:K13) -> 2985000
H15: ROK | I15: =$K$3 -> 0.15 | K15: =I15*K14 -> 447750
H16: Total | K16: =SUM(K14:K15) -> 3432750
H17: Pembulatan | K17: =ROUND(K16,-1) -> 3432750
A18: 2 | B18: 1 Set | D18: Asesoris Riser Pole (Tiang Awal/Kabel Naik) SKTM 95mm² - Tiang Baja 14/350
B19: 1) | C19: Pipa Besi Galvanised diameter 4,0" tebal minimal 2,5mm Panjang 6000mm | H19: batang | I19: 1 | J19: =J8 -> 1998000 | K19: =I19*J19 -> 1998000
B20: 2) | C20: Ornament Cable Band HDG 4 x 8,5" (pemegang Kabel) | H20: buah | I20: 1 | J20: ='Harga Satuan Dasar mat'!G482 -> 172000 | K20: =I20*J20 -> 172000
B21: 3) | C21: Ornament Cable Band HDG 4 x 10,5" (pemegang Pipa sisi atas ) | H21: buah | I21: 1 | J21: =J10 -> 182000 | K21: =I21*J21 -> 182000
B22: 4) | C22: Ornament Cable Band HDG 4 x 10,5" (pemegang Pipa sisi tengah) | H22: buah | I22: 1 | J22: =J21 -> 182000 | K22: =I22*J22 -> 182000
B23: 5) | C23: Ornament Cable Band HDG 4 x 12,5" (pemegang Pipa sisi bawah) | H23: buah | I23: 1 | J23: ='Harga Satuan Dasar mat'!G490 -> 232000 | K23: =I23*J23 -> 232000
B24: 6) | C24: Bolt & Nut 5/8"x70 mm + Washer Galvanis | H24: buah | I24: 12 | J24: =J13 -> 17000 | K24: =I24*J24 -> 204000
H25: Jumlah | K25: =SUM(K19:K24) -> 2970000
H26: ROK | I26: =$K$3 -> 0.15 | K26: =I26*K25 -> 445500
H27: Total | K27: =SUM(K25:K26) -> 3415500
H28: Pembulatan | K28: =ROUND(K27,-1) -> 3415500
A29: 3 | B29: 1 Set | D29: Asesoris Riser Pole (Tiang Awal/Kabel Naik) SKTM 95mm² - Tiang Baja 13/350, Tiang Baja 12/350
B30: 1) | C30: Pipa Besi Galvanised diameter 4,0" tebal minimal 2,5mm Panjang 6000mm | H30: batang | I30: 1 | J30: =J19 -> 1998000 | K30: =I30*J30 -> 1998000
B31: 2) | C31: Ornament Cable Band HDG 4 x 6,5" (pemegang Kabel) | H31: buah | I31: 1 | J31: ='Harga Satuan Dasar mat'!G478 -> 142000 | K31: =I31*J31 -> 142000
B32: 3) | C32: Ornament Cable Band HDG 4 x 8,5" (pemegang Pipa sisi atas ) | H32: buah | I32: 1 | J32: =J20 -> 172000 | K32: =I32*J32 -> 172000
B33: 4) | C33: Ornament Cable Band HDG 4 x 8,5" (pemegang Pipa sisi tengah) | H33: buah | I33: 1 | J33: =J32 -> 172000 | K33: =I33*J33 -> 172000
B34: 5) | C34: Ornament Cable Band HDG 4 x 10,5" (pemegang Pipa sisi bawah) | H34: buah | I34: 1 | J34: =J21 -> 182000 | K34: =I34*J34 -> 182000
B35: 6) | C35: Bolt & Nut 5/8"x70 mm + Washer Galvanis | H35: buah | I35: 12 | J35: =J24 -> 17000 | K35: =I35*J35 -> 204000
H36: Jumlah | K36: =SUM(K30:K35) -> 2870000
H37: ROK | I37: =$K$3 -> 0.15 | K37: =I37*K36 -> 430500
H38: Total | K38: =SUM(K36:K37) -> 3300500
H39: Pembulatan | K39: =ROUND(K38,-1) -> 3300500
A40: 4 | B40: 1 Set | D40: Asesoris Riser Pole (Tiang Awal/Kabel Naik) SKTM 95mm² - Tiang Baja 12/200
B41: 1) | C41: Pipa Besi Galvanised diameter 4,0" tebal minimal 2,5mm Panjang 6000mm | H41: batang | I41: 1 | J41: =J30 -> 1998000 | K41: =I41*J41 -> 1998000
...

Sheet D5 Gardu
A1: ANALISA HARGA SATUAN MATERIAL KONSTRUKSI
A2: GARDU DISTRIBUSI TEGANGAN MENENGAH & KUBIKEL
J3: ROK | K3: 0.15
A4: No | B4: Uraian | H4: Satuan | I4: Volume | J4: Harga (Rp)
J5: Dasar | K5: Harga Satuan
A7: 1 | B7: 1 Set | D7: Cross Arm Dudukan Cut Out di Gardu 1 Tiang - Tiang Beton 14/350, 13/350, 12/350 & 12/200
B8: 1) | C8: Besi UNP 100 (100mm x 50mm x 5mm) Panjang 2000mm HDG | H8: batang | I8: 1 | J8: ='Harga Satuan Dasar mat'!G147 -> 800000 | K8: =I8*J8 -> 800000
B9: 2) | C9: Pole band 1/2 ; Ø 8" HDG | H9: buah | I9: 1 | J9: ='Harga Satuan Dasar mat'!G25 -> 110000 | K9: =I9*J9 -> 110000
B10: 3) | C10: Bolt & nut 5/8 x 50 + ring + 2 mur (galvanis) - M16 | H10: buah | I10: 7 | J10: ='Harga Satuan Dasar mat'!G252 -> 14000 | K10: =I10*J10 -> 98000
B11: 4) | C11: Besi Siku / Besi L 50mm x 50mm x 5mm Panjang 1270mm - HDG u/ Arm Tie | H11: buah | I11: 2 | J11: ='Harga Satuan Dasar mat'!G203 -> 283250 | K11: =I11*J11 -> 566500
B12: 5) | C12: Double Arm Fixing Collar / Arm Tie 2/2 tebal 6mm x lebar 42mm, Ø 8,5" | H12: buah | I12: 1 | J12: ='Harga Satuan Dasar mat'!G104 -> 221500 | K12: =I12*J12 -> 221500
H13: Jumlah | K13: =SUM(K8:K12) -> 1796000
H14: ROK | I14: =$K$3 -> 0.15 | K14: =I14*K13 -> 269400
H15: Total | K15: =SUM(K13:K14) -> 2065400
H16: Pembulatan | K16: =ROUND(K15,-1) -> 2065400
A17: 2 | B17: 1 Set | D17: Cross Arm Dudukan Cut Out di Gardu 1 Tiang - Tiang Baja 14/350
B18: 1) | C18: Besi UNP 100 (100mm x 50mm x 5mm) Panjang 2000mm HDG | H18: batang | I18: 1 | J18: =J8 -> 800000 | K18: =I18*J18 -> 800000
B19: 2) | C19: Pole band 1/2 ; Ø 8,5" HDG | H19: buah | I19: 1 | J19: ='Harga Satuan Dasar mat'!G26 -> 115000 | K19: =I19*J19 -> 115000
B20: 3) | C20: Bolt & nut 5/8 x 50 + ring + 2 mur (galvanis) - M16 | H20: buah | I20: 7 | J20: =J10 -> 14000 | K20: =I20*J20 -> 98000
B21: 4) | C21: Besi Siku / Besi L 50mm x 50mm x 5mm Panjang 1270mm - HDG u/ Arm Tie | H21: buah | I21: 2 | J21: =J11 -> 283250 | K21: =I21*J21 -> 566500
B22: 5) | C22: Double Arm Fixing Collar / Arm Tie 2/2 tebal 6mm x lebar 42mm, Ø 8,5" | H22: buah | I22: 1 | J22: =J12 -> 221500 | K22: =I22*J22 -> 221500
H23: Jumlah | K23: =SUM(K18:K22) -> 1801000
H24: ROK | I24: =$K$3 -> 0.15 | K24: =I24*K23 -> 270150
H25: Total | K25: =SUM(K23:K24) -> 2071150
H26: Pembulatan | K26: =ROUND(K25,-1) -> 2071150
A27: 3 | B27: 1 Set | D27: Cross Arm Dudukan Cut Out di Gardu 1 Tiang - Tiang Baja 13/350 & Tiang Baja 12/350
B28: 1) | C28: Besi UNP 100 (100mm x 50mm x 5mm) Panjang 2000mm HDG | H28: batang | I28: 1 | J28: =J18 -> 800000 | K28: =I28*J28 -> 800000
B29: 2) | C29: Pole band 1/2 ; Ø 6,5" HDG | H29: buah | I29: 1 | J29: ='Harga Satuan Dasar mat'!G22 -> 95500 | K29: =I29*J29 -> 95500
B30: 3) | C30: Bolt & nut 5/8 x 50 + ring + 2 mur (galvanis) - M16 | H30: buah | I30: 7 | J30: =J20 -> 14000 | K30: =I30*J30 -> 98000
B31: 4) | C31: Besi Siku / Besi L 50mm x 50mm x 5mm Panjang 1270mm - HDG u/ Arm Tie | H31: buah | I31: 2 | J31: =J21 -> 283250 | K31: =I31*J31 -> 566500
B32: 5) | C32: Double Arm Fixing Collar / Arm Tie 2/2 tebal 6mm x lebar 42mm, Ø 6,5" | H32: buah | I32: 1 | J32: ='Harga Satuan Dasar mat'!G100 -> 184000 | K32: =I32*J32 -> 184000
H33: Jumlah | K33: =SUM(K28:K32) -> 1744000
H34: ROK | I34: =$K$3 -> 0.15 | K34: =I34*K33 -> 261600
H35: Total | K35: =SUM(K33:K34) -> 2005600
H36: Pembulatan | K36: =ROUND(K35,-1) -> 2005600
A37: 4 | B37: 1 Set | D37: Cross Arm Dudukan Cut Out di Gardu 1 tiang - Tiang Baja 12/200
B38: 1) | C38: Besi UNP 100 (100mm x 50mm x 5mm) Panjang 2000mm HDG | H38: batang | I38: 1 | J38: =J28 -> 800000 | K38: =I38*J38 -> 800000
B39: 2) | C39: Pole band 1/2 ; Ø 5,5" HDG | H39: buah | I39: 1 | J39: ='Harga Satuan Dasar mat'!G20 -> 85000 | K39: =I39*J39 -> 85000
B40: 3) | C40: Bolt & nut 5/8 x 50 + ring + 2 mur (galvanis) - M16 | H40: buah | I40: 7 | J40: =J30 -> 14000 | K40: =I40*J40 -> 98000
B41: 4) | C41: Besi Siku / Besi L 50mm x 50mm x 5mm Panjang 1270mm - HDG u/ Arm Tie | H41: buah | I41: 2 | J41: =J31 -> 283250 | K41: =I41*J41 -> 566500
...

Sheet D6 SKUTR
A1: ANALISA HARGA SATUAN MATERIAL KONSTRUKSI
A2: SALURAN KABEL UDARA TEGANGAN RENDAH (SKUTR)
J3: ROK | K3: 0.15
A4: No | B4: Uraian | H4: Satuan | I4: Volume | J4: Harga (Rp)
J5: Dasar | K5: Harga Satuan
A7: 1 | B7: 1 Set | D7: Suspension Assembly JTR LVTC
B8: 1) | C8: Suspension Bracket | H8: buah | I8: 1 | J8: ='Harga Satuan Dasar mat'!G724 -> 31500 | K8: =I8*J8 -> 31500
B9: 2) | C9: Suspension Clamp | H9: buah | I9: 1 | J9: ='Harga Satuan Dasar mat'!G559 -> 55000 | K9: =I9*J9 -> 55000
B10: 3) | C10: Stainless Steel Strip 20 x 0,7 mm | H10: meter | I10: 1.2 | J10: ='Harga Satuan Dasar mat'!G731 -> 14700 | K10: =I10*J10 -> 17640
B11: 4) | C11: Stopping buckle | H11: buah | I11: 2 | J11: ='Harga Satuan Dasar mat'!G732 -> 3960 | K11: =I11*J11 -> 7920
B12: 5) | C12: Plastic strap | H12: buah | I12: 3 | J12: ='Harga Satuan Dasar mat'!G735 -> 3150 | K12: =I12*J12 -> 9450
H13: Jumlah | K13: =SUM(K8:K12) -> 121510
H14: ROK | I14: =$K$3 -> 0.15 | K14: =I14*K13 -> 18226.5
H15: Total | K15: =SUM(K13:K14) -> 139736.5
H16: Pembulatan | K16: =ROUND(K15,-1) -> 139740
A17: 2 | B17: 1 Set | D17: Large Angle Assembly JTR LVTC
B18: 1) | C18: Tension Bracket | H18: buah | I18: 1 | J18: ='Harga Satuan Dasar mat'!G725 -> 30900 | K18: =I18*J18 -> 30900
B19: 2) | C19: Strain Clamp | H19: buah | I19: 1 | J19: ='Harga Satuan Dasar mat'!G563 -> 75000 | K19: =I19*J19 -> 75000
B20: 3) | C20: Stainless Steel Strip 20 x 0,7 mm | H20: meter | I20: 1.2 | J20: =J10 -> 14700 | K20: =I20*J20 -> 17640
B21: 4) | C21: Stopping buckle | H21: buah | I21: 2 | J21: =J11 -> 3960 | K21: =I21*J21 -> 7920
B22: 5) | C22: Plastic strap | H22: buah | I22: 2 | J22: =J12 -> 3150 | K22: =I22*J22 -> 6300
H23: Jumlah | K23: =SUM(K18:K22) -> 137760
H24: ROK | I24: =$K$3 -> 0.15 | K24: =I24*K23 -> 20664
H25: Total | K25: =SUM(K23:K24) -> 158424
H26: Pembulatan | K26: =ROUND(K25,-1) -> 158420
A27: 3 | B27: 1 Set | D27: Fixed Dead End Assembly JTR LVTC
B28: 1) | C28: Tension Bracket | H28: buah | I28: 1 | J28: =J18 -> 30900 | K28: =I28*J28 -> 30900
B29: 2) | C29: Strain Clamp | H29: buah | I29: 1 | J29: =J19 -> 75000 | K29: =I29*J29 -> 75000
B30: 3) | C30: Stainless Steel Strip 20 x 0,7 mm | H30: meter | I30: 1.2 | J30: =J20 -> 14700 | K30: =I30*J30 -> 17640
B31: 4) | C31: Stopping buckle | H31: buah | I31: 2 | J31: =J21 -> 3960 | K31: =I31*J31 -> 7920
B32: 5) | C32: Plastic strap | H32: buah | I32: 3 | J32: =J22 -> 3150 | K32: =I32*J32 -> 9450
H33: Jumlah | K33: =SUM(K28:K32) -> 140910
H34: ROK | I34: =$K$3 -> 0.15 | K34: =I34*K33 -> 21136.5
H35: Total | K35: =SUM(K33:K34) -> 162046.5
H36: Pembulatan | K36: =ROUND(K35,-1) -> 162050
A37: 4 | B37: 1 Set | D37: Adjustable Dead End Assembly JTR LVTC
B38: 1) | C38: Tension Bracket | H38: buah | I38: 1 | J38: =J28 -> 30900 | K38: =I38*J38 -> 30900
B39: 2) | C39: Strain Clamp | H39: buah | I39: 1 | J39: =J29 -> 75000 | K39: =I39*J39 -> 75000
B40: 3) | C40: Stainless Steel Strip 20 x 0,7 mm | H40: meter | I40: 1.2 | J40: =J30 -> 14700 | K40: =I40*J40 -> 17640
B41: 4) | C41: Stopping buckle | H41: buah | I41: 2 | J41: =J31 -> 3960 | K41: =I41*J41 -> 7920
...

Sheet D7 SKTR
A1: ANALISA HARGA SATUAN MATERIAL KONSTRUKSI
A2: SALURAN KABEL TANAH TEGANGAN RENDAH (SKTR)
J3: ROK | K3: 0.15
A4: No | B4: Uraian | H4: Satuan | I4: Volume | J4: Harga (Rp)
J5: Dasar | K5: Harga Satuan
A7: 1 | B7: 1 Set | D7: Pelindung Kabel Tanah TR
B8: 1) | C8: Concrete slabs 450x150x40 mm | H8: buah | I8: 1 | J8: ='Harga Satuan Dasar mat'!G742 -> 94700 | K8: =I8*J8 -> 94700
B9: 2) | C9: Bata pelindung kabel (Bata merah) | H9: buah | I9: 5 | J9: ='Harga Satuan Dasar mat'!G766 -> 10750 | K9: =I9*J9 -> 53750
H10: Jumlah | K10: =SUM(K8:K9) -> 148450
H11: ROK | I11: =K3 -> 0.15 | K11: =I11*K10 -> 22267.5
H12: Total | K12: =SUM(K10:K11) -> 170717.5
H13: Pembulatan | K13: =ROUND(K12,-1) -> 170720
A14: 2 | B14: 1 Set | D14: Rangka dudukan PHB SKTR
B15: 1) | C15: Besi UNP 100 (100mm x 50mm x 5,0mm) ; HDG 1000mm | H15: batang | I15: 2 | J15: ='Harga Satuan Dasar mat'!G151 -> 400000 | K15: =I15*J15 -> 800000
B16: 2) | C16: Pipa Besi Galvanised diameter 4,0" tebal minimal 2,5mm 1000mm | H16: batang | I16: 3 | J16: ='Harga Satuan Dasar mat'!G328 -> 333000 | K16: =I16*J16 -> 999000
B17: 3) | C17: Bolt & Nut M16 x 120mm | H17: buah | I17: 4 | J17: ='Harga Satuan Dasar mat'!G249 -> 25000 | K17: =I17*J17 -> 100000
B18: 4) | C18: Dyna Bolt 8x85 mm | H18: buah | I18: 4 | J18: ='Harga Satuan Dasar mat'!G744 -> 18700 | K18: =I18*J18 -> 74800
H19: Jumlah | K19: =SUM(K15:K18) -> 1973800
H20: ROK | I20: =I11 -> 0.15 | K20: =I20*K19 -> 296070
H21: Total | K21: =SUM(K19:K20) -> 2269870
H22: Pembulatan | K22: =ROUND(K21,-1) -> 2269870
A23: 3 | B23: 1 M³ | D23: Beton Cor Pondasi
B24: 1) | C24: Semen (PC) | H24: Zak | I24: 8.3 | J24: ='Harga Satuan Dasar mat'!G760 -> 51500 | K24: =I24*J24 -> 427450
B25: 2) | C25: Kerikil Beton | H25: m³ | I25: 0.83 | J25: ='Harga Satuan Dasar mat'!G761 -> 595000 | K25: =I25*J25 -> 493850
B26: 3) | C26: Pasir Pasangan | H26: m³ | I26: 0.54 | J26: ='Harga Satuan Dasar mat'!G764 -> 445500 | K26: =I26*J26 -> 240570
H27: Jumlah | K27: =SUM(K24:K26) -> 1161870
B28: 1 Buah | D28: Beton Pondasi PHB SKTR | H28: m³ | I28: =(90*40*90)/1000000 -> 0.324 | J28: =K27 -> 1161870 | K28: =I28*J28 -> 376445.88
D29: (90cmx40cmx90cm) | H29: ROK | I29: =I20 -> 0.15 | K29: =K28*I29 -> 56466.882
H30: Total | K30: =K28+K29 -> 432912.76
H31: Pembulatan | K31: =ROUND(K30,-1) -> 432910

Sheet D8 SRAPP
A1: ANALISA HARGA SATUAN MATERIAL KONSTRUKSI
A2: SAMBUNGAN RUMAH DAN ALAT PEMBATAS & PENGUKUR
J3: ROK | K3: 0.15
A4: No | B4: Uraian | H4: Satuan | I4: Volume | J4: Harga (Rp)
J5: Dasar | K5: Harga Satuan
A7: 1 | B7: 1 Set | D7: Sambungan Rumah (SR) 1 Phasa melalui saluran udara pada tiang beton 9/200
B8: 1) | C8: Double Arm Fixing Collar 2/2 ; diameter 6" | H8: buah | I8: 1 | J8: ='Harga Satuan Dasar mat'!G99 -> 174250 | K8: =I8*J8 -> 174250
B9: 2) | C9: Service Wedge Clamp 2x6mm - 2x16mm | H9: buah | I9: 1 | J9: ='Harga Satuan Dasar mat'!G734 -> 5700 | K9: =I9*J9 -> 5700
B10: 3) | C10: Stainless Steel Strip | H10: meter | I10: 1 | J10: ='Harga Satuan Dasar mat'!G731 -> 14700 | K10: =I10*J10 -> 14700
B11: 4) | C11: Stoping Buckle | H11: buah | I11: 1 | J11: ='Harga Satuan Dasar mat'!G732 -> 3960 | K11: =I11*J11 -> 3960
B12: 5) | C12: Link 25 x 25 | H12: buah | I12: 1 | J12: ='Harga Satuan Dasar mat'!G733 -> 3650 | K12: =I12*J12 -> 3650
B13: 6) | C13: CCO 10/35-70 mm + Cover | H13: buah | I13: 2 | J13: ='Harga Satuan Dasar mat'!G601 -> 19500 | K13: =I13*J13 -> 39000
